output/results1/rejected.txt
Order{id=2, symbol='FB', side='buy', type='market', price=null, timeStamp=1608917400}
Order{id=3, symbol='GOOG', side='sell', type='market', price=null, timeStamp=1608917400}
Order{id=5, symbol='AMZN', side='buy', type='market', price=null, timeStamp=1608917401}
Order{id=6, symbol='AMZN', side='buy', type='limit', price=null, timeStamp=1608917401}
Order{id=7, symbol='GOOG', side='buy', type='market', price=null, timeStamp=1608917402}
Order{id=10, symbol='FB', side='sell', type='limit', price=265.57, timeStamp=1608917403}
Order{id=11, symbol='GOOG', side='sell', type='limit', price=1732.83, timeStamp=1608917403}
Order{id=12, symbol='GOOG', side='buy', type='market', price=null, timeStamp=1608917404}
Order{id=14, symbol='GOOG', side='buy', type='limit', price=1733.8, timeStamp=1608917405}
Order{id=18, symbol='GOOG', side='sell', type='limit', price=1733.82, timeStamp=1608917406}
Order{id=19, symbol='TSLA', side='sell', type='market', price=null, timeStamp=1608917406}
Order{id=22, symbol='GOOG', side='sell', type='market', price=1732.51, timeStamp=1608917407}
Order{id=24, symbol='AAPL', side='sell', type='market', price=null, timeStamp=1608917408}
Order{id=25, symbol='GOOG', side='sell', type='limit', price=1733.47, timeStamp=1608917408}
Order{id=26, symbol='TSLA', side='sell', type='market', price=null, timeStamp=1608917409}
Order{id=28, symbol='GOOG', side='buy', type='market', price=null, timeStamp=1608917410}
Order{id=29, symbol='AAPL', side='buy', type='market', price=null, timeStamp=1608917410}
Order{id=30, symbol='GOOG', side='buy', type='market', price=null, timeStamp=1608917411}
Order{id=31, symbol='AAPL', side='buy', type='market', price=null, timeStamp=1608917412}
Order{id=32, symbol='FB', side='buy', type='market', price=null, timeStamp=1608917412}
Order{id=34, symbol='GOOG', side='buy', type='limit', price=1733.56, timeStamp=1608917414}
Order{id=35, symbol='FB', side='buy', type='market', price=null, timeStamp=1608917415}
Order{id=37, symbol='FB', side='buy', type='market', price=null, timeStamp=1608917416}
Order{id=38, symbol='FB', side='buy', type='limit', price=265.26, timeStamp=1608917416}
Order{id=41, symbol='FB', side='buy', type='market', price=null, timeStamp=1608917418}
Order{id=43, symbol='FB', side='buy', type='limit', price=265.84, timeStamp=1608917419}
Order{id=44, symbol='GOOG', side='buy', type='market', price=null, timeStamp=1608917420}
Order{id=46, symbol='GOOG', side='buy', type='limit', price=1733.71, timeStamp=1608917421}
Order{id=47, symbol='GOOG', side='buy', type='market', price=null, timeStamp=1608917421}
Order{id=49, symbol='FB', side='buy', type='market', price=null, timeStamp=1608917423}
Order{id=51, symbol='GOOG', side='buy', type='market', price=null, timeStamp=1608917424}
Order{id=52, symbol='GOOG', side='sell', type='limit', price=1733.54, timeStamp=1608917424}
Order{id=55, symbol='AAPL', side='sell', type='market', price=null, timeStamp=1608917426}
Order{id=56, symbol='TSLA', side='buy', type='market', price=null, timeStamp=1608917427}
Order{id=57, symbol='AMZN', side='sell', type='market', price=3171.76, timeStamp=1608917428}
Order{id=58, symbol='AMZN', side='sell', type='market', price=null, timeStamp=1608917428}
Order{id=59, symbol='GOOG', side='sell', type='market', price=null, timeStamp=1608917429}
Order{id=60, symbol='FB', side='buy', type='limit', price=266.37, timeStamp=1608917429}
Order{id=62, symbol='GOOG', side='sell', type='market', price=null, timeStamp=1608917431}
Order{id=64, symbol='GOOG', side='sell', type='limit', price=1733.43, timeStamp=1608917431}
Order{id=65, symbol='FB', side='buy', type='limit', price=265.95, timeStamp=1608917431}
Order{id=70, symbol='GOOG', side='sell', type='limit', price=1732.02, timeStamp=1608917435}
Order{id=71, symbol='FB', side='sell', type='limit', price=265.51, timeStamp=1608917435}
Order{id=72, symbol='FB', side='buy', type='limit', price=266.69, timeStamp=1608917436}
Order{id=74, symbol='GOOG', side='buy', type='market', price=null, timeStamp=1608917437}
Order{id=77, symbol='TSLA', side='sell', type='limit', price=null, timeStamp=1608917440}
Order{id=78, symbol='FB', side='buy', type='market', price=null, timeStamp=1608917440}
Order{id=83, symbol='GOOG', side='buy', type='limit', price=1732.99, timeStamp=1608917442}
Order{id=84, symbol='AAPL', side='sell', type='market', price=130.82, timeStamp=1608917442}
Order{id=86, symbol='FB', side='sell', type='market', price=null, timeStamp=1608917444}
Order{id=87, symbol='FB', side='sell', type='limit', price=265.15, timeStamp=1608917444}
Order{id=94, symbol='FB', side='buy', type='limit', price=265.52, timeStamp=1608917448}
Order{id=95, symbol='GOOG', side='sell', type='market', price=1733.2, timeStamp=1608917448}
Order{id=96, symbol='FB', side='sell', type='limit', price=265.41, timeStamp=1608917449}
Order{id=98, symbol='GOOG', side='sell', type='market', price=null, timeStamp=1608917450}
Order{id=100, symbol='AAPL', side='sell', type='market', price=null, timeStamp=1608917451}
Order{id=101, symbol='GOOG', side='buy', type='limit', price=1733.94, timeStamp=1608917451}
Order{id=103, symbol='TSLA', side='buy', type='market', price=659.74, timeStamp=1608917453}
Order{id=104, symbol='GOOG', side='buy', type='market', price=null, timeStamp=1608917454}
Order{id=105, symbol='GOOG', side='buy', type='limit', price=1733.12, timeStamp=1608917454}
Order{id=106, symbol='GOOG', side='buy', type='limit', price=1733.23, timeStamp=1608917454}
Order{id=109, symbol='FB', side='sell', type='limit', price=266.14, timeStamp=1608917455}
Order{id=110, symbol='FB', side='buy', type='limit', price=265.77, timeStamp=1608917456}
Order{id=112, symbol='TSLA', side='sell', type='limit', price=null, timeStamp=1608917457}
Order{id=114, symbol='GOOG', side='buy', type='market', price=null, timeStamp=1608917459}
Order{id=115, symbol='AMZN', side='buy', type='limit', price=null, timeStamp=1608917459}
Order{id=116, symbol='AAPL', side='sell', type='market', price=null, timeStamp=1608917460}
Order{id=119, symbol='FB', side='buy', type='limit', price=265.27, timeStamp=1608917462}
Order{id=121, symbol='GOOG', side='sell', type='limit', price=1732.58, timeStamp=1608917464}
Order{id=123, symbol='GOOG', side='sell', type='limit', price=1733.34, timeStamp=1608917465}
Order{id=124, symbol='FB', side='sell', type='market', price=null, timeStamp=1608917466}
Order{id=125, symbol='AAPL', side='buy', type='market', price=null, timeStamp=1608917467}
Order{id=128, symbol='FB', side='buy', type='limit', price=266.11, timeStamp=1608917468}
Order{id=130, symbol='FB', side='buy', type='limit', price=265.97, timeStamp=1608917469}
Order{id=131, symbol='FB', side='buy', type='market', price=null, timeStamp=1608917470}
Order{id=133, symbol='FB', side='sell', type='market', price=null, timeStamp=1608917471}
Order{id=134, symbol='GOOG', side='sell', type='limit', price=1732.29, timeStamp=1608917472}
Order{id=136, symbol='FB', side='buy', type='limit', price=266.66, timeStamp=1608917472}
Order{id=137, symbol='GOOG', side='sell', type='limit', price=1733.46, timeStamp=1608917473}
Order{id=139, symbol='FB', side='buy', type='limit', price=266.9, timeStamp=1608917474}
Order{id=142, symbol='GOOG', side='sell', type='limit', price=1732.95, timeStamp=1608917476}
Order{id=144, symbol='GOOG', side='sell', type='limit', price=1732.8, timeStamp=1608917476}
Order{id=146, symbol='GOOG', side='buy', type='market', price=null, timeStamp=1608917477}
Order{id=149, symbol='FB', side='sell', type='limit', price=266.81, timeStamp=1608917479}
Order{id=156, symbol='FB', side='buy', type='market', price=null, timeStamp=1608917483}
Order{id=160, symbol='GOOG', side='buy', type='limit', price=null, timeStamp=1608917485}
Order{id=161, symbol='FB', side='buy', type='market', price=null, timeStamp=1608917486}
Order{id=162, symbol='FB', side='sell', type='limit', price=266.15, timeStamp=1608917486}
Order{id=164, symbol='FB', side='buy', type='limit', price=266.02, timeStamp=1608917487}
Order{id=165, symbol='GOOG', side='buy', type='market', price=null, timeStamp=1608917488}
