output/results1/trades.txt
Matched Trades
Order{id=38097, symbol='TSLA', side='buy', type='market', price=null, timeStamp=1608936633}
Order{id=38068, symbol='TSLA', side='sell', type='limit', price=658.2, timeStamp=1608936619}

Order{id=19639, symbol='AMZN', side='buy', type='limit', price=3171.85, timeStamp=1608927333}
Order{id=19541, symbol='AMZN', side='sell', type='limit', price=3171.24, timeStamp=1608927279}

Order{id=19794, symbol='AMZN', side='sell', type='market', price=null, timeStamp=1608927409}
Order{id=19793, symbol='AMZN', side='buy', type='limit', price=3170.68, timeStamp=1608927408}

Order{id=6452, symbol='AMZN', side='buy', type='market', price=null, timeStamp=1608920662}
Order{id=6447, symbol='AMZN', side='sell', type='limit', price=3170.42, timeStamp=1608920659}

Order{id=41212, symbol='AMZN', side='sell', type='market', price=null, timeStamp=1608938190}
Order{id=41157, symbol='AMZN', side='buy', type='limit', price=3170.03, timeStamp=1608938163}

Order{id=13238, symbol='TSLA', side='buy', type='limit', price=659.86, timeStamp=1608924076}
Order{id=13234, symbol='TSLA', side='sell', type='limit', price=658.1, timeStamp=1608924075}

Order{id=19877, symbol='TSLA', side='sell', type='market', price=null, timeStamp=1608927453}
Order{id=19835, symbol='TSLA', side='buy', type='limit', price=658.44, timeStamp=1608927431}

Order{id=45895, symbol='AAPL', side='sell', type='market', price=null, timeStamp=1608940536}
Order{id=45892, symbol='AAPL', side='buy', type='limit', price=130.44, timeStamp=1608940535}

Order{id=10054, symbol='AMZN', side='sell', type='limit', price=3170.17, timeStamp=1608922482}
Order{id=10040, symbol='AMZN', side='buy', type='limit', price=3170.58, timeStamp=1608922473}

Order{id=11118, symbol='AAPL', side='sell', type='limit', price=130.16, timeStamp=1608923023}
Order{id=11021, symbol='AAPL', side='buy', type='limit', price=130.44, timeStamp=1608922980}

Order{id=2038, symbol='AMZN', side='buy', type='market', price=null, timeStamp=1608918436}
Order{id=2024, symbol='AMZN', side='sell', type='limit', price=3171.77, timeStamp=1608918429}

Order{id=28268, symbol='AMZN', side='buy', type='limit', price=3170.89, timeStamp=1608931699}
Order{id=28263, symbol='AMZN', side='sell', type='limit', price=3170.17, timeStamp=1608931697}

Order{id=30273, symbol='AAPL', side='sell', type='limit', price=131.11, timeStamp=1608932702}
Order{id=30262, symbol='AAPL', side='buy', type='limit', price=131.17, timeStamp=1608932697}

Order{id=33539, symbol='AAPL', side='sell', type='limit', price=130.51, timeStamp=1608934361}
Order{id=33536, symbol='AAPL', side='buy', type='limit', price=130.82, timeStamp=1608934359}

Order{id=43655, symbol='AAPL', side='sell', type='market', price=null, timeStamp=1608939423}
Order{id=43639, symbol='AAPL', side='buy', type='limit', price=130.39, timeStamp=1608939413}

Order{id=18805, symbol='AAPL', side='buy', type='market', price=null, timeStamp=1608926919}
Order{id=18802, symbol='AAPL', side='sell', type='limit', price=130.52, timeStamp=1608926918}

Order{id=25894, symbol='TSLA', side='buy', type='market', price=null, timeStamp=1608930517}
Order{id=25887, symbol='TSLA', side='sell', type='limit', price=658.09, timeStamp=1608930513}

Order{id=35499, symbol='TSLA', side='sell', type='market', price=null, timeStamp=1608935334}
Order{id=35487, symbol='TSLA', side='buy', type='limit', price=658.27, timeStamp=1608935329}

Order{id=27183, symbol='AMZN', side='buy', type='limit', price=3171.5, timeStamp=1608931156}
Order{id=27164, symbol='AMZN', side='sell', type='limit', price=3170.71, timeStamp=1608931146}

Order{id=40302, symbol='AMZN', side='sell', type='market', price=null, timeStamp=1608937733}
Order{id=40043, symbol='AMZN', side='buy', type='limit', price=3170.14, timeStamp=1608937604}

Order{id=35580, symbol='AAPL', side='sell', type='market', price=null, timeStamp=1608935378}
Order{id=35568, symbol='AAPL', side='buy', type='limit', price=131.84, timeStamp=1608935373}

Order{id=25932, symbol='AMZN', side='buy', type='market', price=null, timeStamp=1608930536}
Order{id=25680, symbol='AMZN', side='sell', type='limit', price=3171.92, timeStamp=1608930405}

Order{id=31028, symbol='AMZN', side='sell', type='market', price=null, timeStamp=1608933086}
Order{id=31015, symbol='AMZN', side='buy', type='limit', price=3171.67, timeStamp=1608933078}

Order{id=18722, symbol='TSLA', side='buy', type='market', price=null, timeStamp=1608926875}
Order{id=18699, symbol='TSLA', side='sell', type='limit', price=658.11, timeStamp=1608926863}

Order{id=34192, symbol='TSLA', side='sell', type='limit', price=658.79, timeStamp=1608934691}
Order{id=34182, symbol='TSLA', side='buy', type='limit', price=658.84, timeStamp=1608934687}

Order{id=14959, symbol='AMZN', side='buy', type='market', price=null, timeStamp=1608924937}
Order{id=14927, symbol='AMZN', side='sell', type='limit', price=3171.17, timeStamp=1608924920}

Order{id=3408, symbol='TSLA', side='buy', type='market', price=null, timeStamp=1608919134}
Order{id=3366, symbol='TSLA', side='sell', type='limit', price=659.04, timeStamp=1608919118}

Order{id=45912, symbol='AAPL', side='buy', type='market', price=null, timeStamp=1608940547}
Order{id=45902, symbol='AAPL', side='sell', type='limit', price=131.88, timeStamp=1608940540}

Order{id=5991, symbol='AAPL', side='sell', type='market', price=null, timeStamp=1608920430}
Order{id=5981, symbol='AAPL', side='buy', type='limit', price=131.6, timeStamp=1608920427}

Order{id=2030, symbol='TSLA', side='buy', type='limit', price=659.28, timeStamp=1608918432}
Order{id=2028, symbol='TSLA', side='sell', type='limit', price=659.08, timeStamp=1608918431}

Order{id=6506, symbol='TSLA', side='buy', type='market', price=null, timeStamp=1608920691}
Order{id=6456, symbol='TSLA', side='sell', type='limit', price=659.7, timeStamp=1608920664}

Order{id=42279, symbol='AMZN', side='sell', type='market', price=null, timeStamp=1608938733}
Order{id=42266, symbol='AMZN', side='buy', type='limit', price=3170.39, timeStamp=1608938726}

Order{id=9471, symbol='TSLA', side='sell', type='market', price=null, timeStamp=1608922186}
Order{id=9462, symbol='TSLA', side='buy', type='limit', price=659.11, timeStamp=1608922182}

Order{id=28352, symbol='AMZN', side='sell', type='market', price=null, timeStamp=1608931740}
Order{id=28351, symbol='AMZN', side='buy', type='limit', price=3171.59, timeStamp=1608931739}

Order{id=34555, symbol='AMZN', side='sell', type='market', price=3170.2, timeStamp=1608934877}
Order{id=34545, symbol='AMZN', side='buy', type='limit', price=3171.15, timeStamp=1608934870}

Order{id=1262, symbol='TSLA', side='buy', type='market', price=659.91, timeStamp=1608918035}
Order{id=1261, symbol='TSLA', side='sell', type='limit', price=659.56, timeStamp=1608918034}

Order{id=27661, symbol='AMZN', side='buy', type='market', price=3170.56, timeStamp=1608931397}
Order{id=27639, symbol='AMZN', side='sell', type='limit', price=3171.46, timeStamp=1608931386}

Order{id=26190, symbol='AMZN', side='buy', type='market', price=null, timeStamp=1608930660}
Order{id=26188, symbol='AMZN', side='sell', type='limit', price=3170.99, timeStamp=1608930659}

Order{id=41559, symbol='AMZN', side='sell', type='limit', price=3170.42, timeStamp=1608938365}
Order{id=41558, symbol='AMZN', side='buy', type='limit', price=3171.42, timeStamp=1608938365}

Order{id=25986, symbol='AMZN', side='buy', type='limit', price=3171.62, timeStamp=1608930560}
Order{id=25947, symbol='AMZN', side='sell', type='limit', price=3171.49, timeStamp=1608930542}

Order{id=42420, symbol='AMZN', side='buy', type='market', price=null, timeStamp=1608938800}
Order{id=42349, symbol='AMZN', side='sell', type='limit', price=3171.78, timeStamp=1608938766}

Order{id=26744, symbol='TSLA', side='sell', type='market', price=null, timeStamp=1608930930}
Order{id=26435, symbol='TSLA', side='buy', type='limit', price=658.28, timeStamp=1608930775}

Order{id=4576, symbol='TSLA', side='sell', type='market', price=null, timeStamp=1608919732}
Order{id=4516, symbol='TSLA', side='buy', type='limit', price=658.39, timeStamp=1608919698}
